{
 "cells": [
  {
   "cell_type": "code",
   "execution_count": 1,
   "metadata": {},
   "outputs": [
    {
     "name": "stderr",
     "output_type": "stream",
     "text": [
      "2023-03-29 14:34:16.368647: I tensorflow/tsl/cuda/cudart_stub.cc:28] Could not find cuda drivers on your machine, GPU will not be used.\n",
      "2023-03-29 14:34:16.411197: I tensorflow/tsl/cuda/cudart_stub.cc:28] Could not find cuda drivers on your machine, GPU will not be used.\n",
      "2023-03-29 14:34:16.412955: I tensorflow/core/platform/cpu_feature_guard.cc:182] This TensorFlow binary is optimized to use available CPU instructions in performance-critical operations.\n",
      "To enable the following instructions: AVX2 FMA, in other operations, rebuild TensorFlow with the appropriate compiler flags.\n",
      "2023-03-29 14:34:17.320464: W tensorflow/compiler/tf2tensorrt/utils/py_utils.cc:38] TF-TRT Warning: Could not find TensorRT\n"
     ]
    },
    {
     "name": "stdout",
     "output_type": "stream",
     "text": [
      "TensorFlow version: 2.12.0\n"
     ]
    },
    {
     "name": "stderr",
     "output_type": "stream",
     "text": [
      "/home/abduraxim/Documents/tensorflow_imagenet/venv/lib/python3.10/site-packages/tqdm/auto.py:21: TqdmWarning: IProgress not found. Please update jupyter and ipywidgets. See https://ipywidgets.readthedocs.io/en/stable/user_install.html\n",
      "  from .autonotebook import tqdm as notebook_tqdm\n"
     ]
    }
   ],
   "source": [
    "import tensorflow as tf\n",
    "print(\"TensorFlow version:\", tf.__version__)\n",
    "\n",
    "from tensorflow.keras.layers import Dense, Flatten, Conv2D, MaxPool2D\n",
    "from tensorflow.keras import Model\n",
    "import tensorflow_datasets as tfds\n",
    "import numpy as np\n"
   ]
  },
  {
   "cell_type": "code",
   "execution_count": 26,
   "metadata": {},
   "outputs": [
    {
     "data": {
      "text/plain": [
       "<tensorflow.python.eager.context._EagerDeviceContext at 0x7fed97586fc0>"
      ]
     },
     "execution_count": 26,
     "metadata": {},
     "output_type": "execute_result"
    }
   ],
   "source": [
    "tf.device('GPU')"
   ]
  },
  {
   "cell_type": "code",
   "execution_count": 2,
   "metadata": {},
   "outputs": [
    {
     "name": "stderr",
     "output_type": "stream",
     "text": [
      "2023-03-29 14:34:18.600700: I tensorflow/compiler/xla/stream_executor/cuda/cuda_gpu_executor.cc:996] successful NUMA node read from SysFS had negative value (-1), but there must be at least one NUMA node, so returning NUMA node zero. See more at https://github.com/torvalds/linux/blob/v6.0/Documentation/ABI/testing/sysfs-bus-pci#L344-L355\n",
      "2023-03-29 14:34:18.601294: W tensorflow/core/common_runtime/gpu/gpu_device.cc:1956] Cannot dlopen some GPU libraries. Please make sure the missing libraries mentioned above are installed properly if you would like to use GPU. Follow the guide at https://www.tensorflow.org/install/gpu for how to download and setup the required libraries for your platform.\n",
      "Skipping registering GPU devices...\n"
     ]
    }
   ],
   "source": [
    "dataset = tfds.load(\"imagenet_resized\", split = \"train\")"
   ]
  },
  {
   "cell_type": "code",
   "execution_count": 3,
   "metadata": {},
   "outputs": [],
   "source": [
    "img = tfds.builder('imagenet_resized')\n",
    "img = img.as_dataset()\n"
   ]
  },
  {
   "cell_type": "code",
   "execution_count": 5,
   "metadata": {},
   "outputs": [],
   "source": [
    "image = []\n",
    "label = []"
   ]
  },
  {
   "cell_type": "code",
   "execution_count": 6,
   "metadata": {},
   "outputs": [
    {
     "name": "stderr",
     "output_type": "stream",
     "text": [
      "2023-03-29 14:34:19.295880: I tensorflow/core/common_runtime/executor.cc:1197] [/device:CPU:0] (DEBUG INFO) Executor start aborting (this does not indicate an error and you can ignore this message): INVALID_ARGUMENT: You must feed a value for placeholder tensor 'Placeholder/_4' with dtype int64 and shape [4]\n",
      "\t [[{{node Placeholder/_4}}]]\n",
      "2023-03-29 14:34:19.296327: I tensorflow/core/common_runtime/executor.cc:1197] [/device:CPU:0] (DEBUG INFO) Executor start aborting (this does not indicate an error and you can ignore this message): INVALID_ARGUMENT: You must feed a value for placeholder tensor 'Placeholder/_2' with dtype string and shape [4]\n",
      "\t [[{{node Placeholder/_2}}]]\n"
     ]
    }
   ],
   "source": [
    "for example in tfds.as_numpy(img['train']):\n",
    "      image.append(example['image'])\n",
    "      label.append(example['label'])"
   ]
  },
  {
   "cell_type": "code",
   "execution_count": 7,
   "metadata": {},
   "outputs": [],
   "source": [
    "images = np.array(image)\n",
    "labels = np.array(label)\n"
   ]
  },
  {
   "cell_type": "code",
   "execution_count": 27,
   "metadata": {},
   "outputs": [],
   "source": [
    "test_ds = tf.data.Dataset.from_tensor_slices((images, labels)).batch(32)"
   ]
  },
  {
   "cell_type": "code",
   "execution_count": 34,
   "metadata": {},
   "outputs": [
    {
     "data": {
      "text/plain": [
       "(1281167, 8, 8, 3)"
      ]
     },
     "execution_count": 34,
     "metadata": {},
     "output_type": "execute_result"
    }
   ],
   "source": [
    "images.shape"
   ]
  },
  {
   "cell_type": "code",
   "execution_count": 37,
   "metadata": {},
   "outputs": [],
   "source": [
    "class MyModel(Model):\n",
    "    def __init__(self):\n",
    "        super(MyModel, self).__init__()\n",
    "        self.conv1 = Conv2D(32, 3, activation='relu')\n",
    "        self.max1 = MaxPool2D((2, 2))\n",
    "        self.conv2 = Conv2D(16, (3, 3), activation='relu')\n",
    "        self.flatten = Flatten()\n",
    "        self.d1 = Dense(128, activation='relu')\n",
    "        self.d2 = Dense(1000)\n",
    "\n",
    "    def call(self, x):\n",
    "        x = self.conv1(x)\n",
    "        x = self.max1(x)\n",
    "        x = self.conv2(x)\n",
    "        x = self.flatten(x)\n",
    "        x = self.d1(x)\n",
    "        return self.d2(x)\n",
    "\n",
    "# Create an instance of the model\n",
    "model = MyModel()"
   ]
  },
  {
   "cell_type": "code",
   "execution_count": 38,
   "metadata": {},
   "outputs": [],
   "source": [
    "loss_object = tf.keras.losses.SparseCategoricalCrossentropy(from_logits=True)\n",
    "optimizer = tf.keras.optimizers.Adam()"
   ]
  },
  {
   "cell_type": "code",
   "execution_count": 39,
   "metadata": {},
   "outputs": [],
   "source": [
    "train_loss = tf.keras.metrics.Mean(name='train_loss')\n",
    "train_accuracy = tf.keras.metrics.SparseCategoricalAccuracy(name='train_accuracy')\n",
    "\n",
    "test_loss = tf.keras.metrics.Mean(name='test_loss')\n",
    "test_accuracy = tf.keras.metrics.SparseCategoricalAccuracy(name='test_accuracy')"
   ]
  },
  {
   "cell_type": "code",
   "execution_count": 40,
   "metadata": {},
   "outputs": [],
   "source": [
    "@tf.function\n",
    "def train_step(images, labels):\n",
    "  with tf.GradientTape() as tape:\n",
    "    # training=True is only needed if there are layers with different\n",
    "    # behavior during training versus inference (e.g. Dropout).\n",
    "    predictions = model(images, training=True)\n",
    "    loss = loss_object(labels, predictions)\n",
    "  gradients = tape.gradient(loss, model.trainable_variables)\n",
    "  optimizer.apply_gradients(zip(gradients, model.trainable_variables))\n",
    "\n",
    "  train_loss(loss)\n",
    "  train_accuracy(labels, predictions)"
   ]
  },
  {
   "cell_type": "code",
   "execution_count": 41,
   "metadata": {},
   "outputs": [],
   "source": [
    "@tf.function\n",
    "def test_step(images, labels):\n",
    "  # training=False is only needed if there are layers with different\n",
    "  # behavior during training versus inference (e.g. Dropout).\n",
    "  predictions = model(images, training=False)\n",
    "  t_loss = loss_object(labels, predictions)\n",
    "\n",
    "  test_loss(t_loss)\n",
    "  test_accuracy(labels, predictions)"
   ]
  },
  {
   "cell_type": "code",
   "execution_count": 42,
   "metadata": {},
   "outputs": [
    {
     "ename": "TypeError",
     "evalue": "in user code:\n\n    File \"/tmp/ipykernel_12974/812321113.py\", line 6, in train_step  *\n        predictions = model(images, training=True)\n    File \"/home/abduraxim/Documents/tensorflow_imagenet/venv/lib/python3.10/site-packages/keras/utils/traceback_utils.py\", line 70, in error_handler  **\n        raise e.with_traceback(filtered_tb) from None\n    File \"/tmp/__autograph_generated_file6kf3m2sa.py\", line 10, in tf__call\n        x = ag__.converted_call(ag__.ld(self).conv1, (ag__.ld(x),), None, fscope)\n\n    TypeError: Exception encountered when calling layer 'my_model_5' (type MyModel).\n    \n    in user code:\n    \n        File \"/tmp/ipykernel_12974/609902969.py\", line 12, in call  *\n            x = self.conv1(x)\n        File \"/home/abduraxim/Documents/tensorflow_imagenet/venv/lib/python3.10/site-packages/keras/utils/traceback_utils.py\", line 70, in error_handler  **\n            raise e.with_traceback(filtered_tb) from None\n    \n        TypeError: Exception encountered when calling layer 'conv2d_10' (type Conv2D).\n        \n        Value passed to parameter 'input' has DataType uint8 not in list of allowed values: float16, bfloat16, float32, float64, int32\n        \n        Call arguments received by layer 'conv2d_10' (type Conv2D):\n          • inputs=tf.Tensor(shape=(32, 8, 8, 3), dtype=uint8)\n    \n    \n    Call arguments received by layer 'my_model_5' (type MyModel):\n      • x=tf.Tensor(shape=(32, 8, 8, 3), dtype=uint8)\n",
     "output_type": "error",
     "traceback": [
      "\u001b[0;31m---------------------------------------------------------------------------\u001b[0m",
      "\u001b[0;31mTypeError\u001b[0m                                 Traceback (most recent call last)",
      "Cell \u001b[0;32mIn[42], line 11\u001b[0m\n\u001b[1;32m      8\u001b[0m   test_accuracy\u001b[39m.\u001b[39mreset_states()\n\u001b[1;32m     10\u001b[0m   \u001b[39mfor\u001b[39;00m img, lbl \u001b[39min\u001b[39;00m test_ds:\n\u001b[0;32m---> 11\u001b[0m     train_step(img, lbl)\n\u001b[1;32m     13\u001b[0m \u001b[39m#   for test_images, test_labels in test_ds:\u001b[39;00m\n\u001b[1;32m     14\u001b[0m \u001b[39m#     test_step(test_images, test_labels)\u001b[39;00m\n\u001b[1;32m     16\u001b[0m   \u001b[39mprint\u001b[39m(\n\u001b[1;32m     17\u001b[0m     \u001b[39mf\u001b[39m\u001b[39m'\u001b[39m\u001b[39mEpoch \u001b[39m\u001b[39m{\u001b[39;00mepoch\u001b[39m \u001b[39m\u001b[39m+\u001b[39m\u001b[39m \u001b[39m\u001b[39m1\u001b[39m\u001b[39m}\u001b[39;00m\u001b[39m, \u001b[39m\u001b[39m'\u001b[39m\n\u001b[1;32m     18\u001b[0m     \u001b[39mf\u001b[39m\u001b[39m'\u001b[39m\u001b[39mLoss: \u001b[39m\u001b[39m{\u001b[39;00mtrain_loss\u001b[39m.\u001b[39mresult()\u001b[39m}\u001b[39;00m\u001b[39m, \u001b[39m\u001b[39m'\u001b[39m\n\u001b[0;32m   (...)\u001b[0m\n\u001b[1;32m     21\u001b[0m     \u001b[39mf\u001b[39m\u001b[39m'\u001b[39m\u001b[39mTest Accuracy: \u001b[39m\u001b[39m{\u001b[39;00mtest_accuracy\u001b[39m.\u001b[39mresult()\u001b[39m \u001b[39m\u001b[39m*\u001b[39m\u001b[39m \u001b[39m\u001b[39m100\u001b[39m\u001b[39m}\u001b[39;00m\u001b[39m'\u001b[39m\n\u001b[1;32m     22\u001b[0m   )\n",
      "File \u001b[0;32m~/Documents/tensorflow_imagenet/venv/lib/python3.10/site-packages/tensorflow/python/util/traceback_utils.py:153\u001b[0m, in \u001b[0;36mfilter_traceback.<locals>.error_handler\u001b[0;34m(*args, **kwargs)\u001b[0m\n\u001b[1;32m    151\u001b[0m \u001b[39mexcept\u001b[39;00m \u001b[39mException\u001b[39;00m \u001b[39mas\u001b[39;00m e:\n\u001b[1;32m    152\u001b[0m   filtered_tb \u001b[39m=\u001b[39m _process_traceback_frames(e\u001b[39m.\u001b[39m__traceback__)\n\u001b[0;32m--> 153\u001b[0m   \u001b[39mraise\u001b[39;00m e\u001b[39m.\u001b[39mwith_traceback(filtered_tb) \u001b[39mfrom\u001b[39;00m \u001b[39mNone\u001b[39m\n\u001b[1;32m    154\u001b[0m \u001b[39mfinally\u001b[39;00m:\n\u001b[1;32m    155\u001b[0m   \u001b[39mdel\u001b[39;00m filtered_tb\n",
      "File \u001b[0;32m/tmp/__autograph_generated_fileda_nnvjr.py:9\u001b[0m, in \u001b[0;36mouter_factory.<locals>.inner_factory.<locals>.tf__train_step\u001b[0;34m(images, labels)\u001b[0m\n\u001b[1;32m      7\u001b[0m \u001b[39mwith\u001b[39;00m ag__\u001b[39m.\u001b[39mFunctionScope(\u001b[39m'\u001b[39m\u001b[39mtrain_step\u001b[39m\u001b[39m'\u001b[39m, \u001b[39m'\u001b[39m\u001b[39mfscope\u001b[39m\u001b[39m'\u001b[39m, ag__\u001b[39m.\u001b[39mConversionOptions(recursive\u001b[39m=\u001b[39m\u001b[39mTrue\u001b[39;00m, user_requested\u001b[39m=\u001b[39m\u001b[39mTrue\u001b[39;00m, optional_features\u001b[39m=\u001b[39m(), internal_convert_user_code\u001b[39m=\u001b[39m\u001b[39mTrue\u001b[39;00m)) \u001b[39mas\u001b[39;00m fscope:\n\u001b[1;32m      8\u001b[0m     \u001b[39mwith\u001b[39;00m ag__\u001b[39m.\u001b[39mld(tf)\u001b[39m.\u001b[39mGradientTape() \u001b[39mas\u001b[39;00m tape:\n\u001b[0;32m----> 9\u001b[0m         predictions \u001b[39m=\u001b[39m ag__\u001b[39m.\u001b[39;49mconverted_call(ag__\u001b[39m.\u001b[39;49mld(model), (ag__\u001b[39m.\u001b[39;49mld(images),), \u001b[39mdict\u001b[39;49m(training\u001b[39m=\u001b[39;49m\u001b[39mTrue\u001b[39;49;00m), fscope)\n\u001b[1;32m     10\u001b[0m         loss \u001b[39m=\u001b[39m ag__\u001b[39m.\u001b[39mconverted_call(ag__\u001b[39m.\u001b[39mld(loss_object), (ag__\u001b[39m.\u001b[39mld(labels), ag__\u001b[39m.\u001b[39mld(predictions)), \u001b[39mNone\u001b[39;00m, fscope)\n\u001b[1;32m     11\u001b[0m     gradients \u001b[39m=\u001b[39m ag__\u001b[39m.\u001b[39mconverted_call(ag__\u001b[39m.\u001b[39mld(tape)\u001b[39m.\u001b[39mgradient, (ag__\u001b[39m.\u001b[39mld(loss), ag__\u001b[39m.\u001b[39mld(model)\u001b[39m.\u001b[39mtrainable_variables), \u001b[39mNone\u001b[39;00m, fscope)\n",
      "File \u001b[0;32m~/Documents/tensorflow_imagenet/venv/lib/python3.10/site-packages/keras/utils/traceback_utils.py:70\u001b[0m, in \u001b[0;36mfilter_traceback.<locals>.error_handler\u001b[0;34m(*args, **kwargs)\u001b[0m\n\u001b[1;32m     67\u001b[0m     filtered_tb \u001b[39m=\u001b[39m _process_traceback_frames(e\u001b[39m.\u001b[39m__traceback__)\n\u001b[1;32m     68\u001b[0m     \u001b[39m# To get the full stack trace, call:\u001b[39;00m\n\u001b[1;32m     69\u001b[0m     \u001b[39m# `tf.debugging.disable_traceback_filtering()`\u001b[39;00m\n\u001b[0;32m---> 70\u001b[0m     \u001b[39mraise\u001b[39;00m e\u001b[39m.\u001b[39mwith_traceback(filtered_tb) \u001b[39mfrom\u001b[39;00m \u001b[39mNone\u001b[39m\n\u001b[1;32m     71\u001b[0m \u001b[39mfinally\u001b[39;00m:\n\u001b[1;32m     72\u001b[0m     \u001b[39mdel\u001b[39;00m filtered_tb\n",
      "File \u001b[0;32m/tmp/__autograph_generated_file6kf3m2sa.py:10\u001b[0m, in \u001b[0;36mouter_factory.<locals>.inner_factory.<locals>.tf__call\u001b[0;34m(self, x)\u001b[0m\n\u001b[1;32m      8\u001b[0m do_return \u001b[39m=\u001b[39m \u001b[39mFalse\u001b[39;00m\n\u001b[1;32m      9\u001b[0m retval_ \u001b[39m=\u001b[39m ag__\u001b[39m.\u001b[39mUndefinedReturnValue()\n\u001b[0;32m---> 10\u001b[0m x \u001b[39m=\u001b[39m ag__\u001b[39m.\u001b[39;49mconverted_call(ag__\u001b[39m.\u001b[39;49mld(\u001b[39mself\u001b[39;49m)\u001b[39m.\u001b[39;49mconv1, (ag__\u001b[39m.\u001b[39;49mld(x),), \u001b[39mNone\u001b[39;49;00m, fscope)\n\u001b[1;32m     11\u001b[0m x \u001b[39m=\u001b[39m ag__\u001b[39m.\u001b[39mconverted_call(ag__\u001b[39m.\u001b[39mld(\u001b[39mself\u001b[39m)\u001b[39m.\u001b[39mmax1, (ag__\u001b[39m.\u001b[39mld(x),), \u001b[39mNone\u001b[39;00m, fscope)\n\u001b[1;32m     12\u001b[0m x \u001b[39m=\u001b[39m ag__\u001b[39m.\u001b[39mconverted_call(ag__\u001b[39m.\u001b[39mld(\u001b[39mself\u001b[39m)\u001b[39m.\u001b[39mconv2, (ag__\u001b[39m.\u001b[39mld(x),), \u001b[39mNone\u001b[39;00m, fscope)\n",
      "\u001b[0;31mTypeError\u001b[0m: in user code:\n\n    File \"/tmp/ipykernel_12974/812321113.py\", line 6, in train_step  *\n        predictions = model(images, training=True)\n    File \"/home/abduraxim/Documents/tensorflow_imagenet/venv/lib/python3.10/site-packages/keras/utils/traceback_utils.py\", line 70, in error_handler  **\n        raise e.with_traceback(filtered_tb) from None\n    File \"/tmp/__autograph_generated_file6kf3m2sa.py\", line 10, in tf__call\n        x = ag__.converted_call(ag__.ld(self).conv1, (ag__.ld(x),), None, fscope)\n\n    TypeError: Exception encountered when calling layer 'my_model_5' (type MyModel).\n    \n    in user code:\n    \n        File \"/tmp/ipykernel_12974/609902969.py\", line 12, in call  *\n            x = self.conv1(x)\n        File \"/home/abduraxim/Documents/tensorflow_imagenet/venv/lib/python3.10/site-packages/keras/utils/traceback_utils.py\", line 70, in error_handler  **\n            raise e.with_traceback(filtered_tb) from None\n    \n        TypeError: Exception encountered when calling layer 'conv2d_10' (type Conv2D).\n        \n        Value passed to parameter 'input' has DataType uint8 not in list of allowed values: float16, bfloat16, float32, float64, int32\n        \n        Call arguments received by layer 'conv2d_10' (type Conv2D):\n          • inputs=tf.Tensor(shape=(32, 8, 8, 3), dtype=uint8)\n    \n    \n    Call arguments received by layer 'my_model_5' (type MyModel):\n      • x=tf.Tensor(shape=(32, 8, 8, 3), dtype=uint8)\n"
     ]
    }
   ],
   "source": [
    "EPOCHS = 5\n",
    "\n",
    "for epoch in range(EPOCHS):\n",
    "  # Reset the metrics at the start of the next epoch\n",
    "  train_loss.reset_states()\n",
    "  train_accuracy.reset_states()\n",
    "  test_loss.reset_states()\n",
    "  test_accuracy.reset_states()\n",
    "\n",
    "  for img, lbl in test_ds:\n",
    "    train_step(img, lbl)\n",
    "\n",
    "#   for test_images, test_labels in test_ds:\n",
    "#     test_step(test_images, test_labels)\n",
    "\n",
    "  print(\n",
    "    f'Epoch {epoch + 1}, '\n",
    "    f'Loss: {train_loss.result()}, '\n",
    "    f'Accuracy: {train_accuracy.result() * 100}, '\n",
    "    f'Test Loss: {test_loss.result()}, '\n",
    "    f'Test Accuracy: {test_accuracy.result() * 100}'\n",
    "  )"
   ]
  },
  {
   "cell_type": "code",
   "execution_count": null,
   "metadata": {},
   "outputs": [],
   "source": []
  }
 ],
 "metadata": {
  "kernelspec": {
   "display_name": "venv",
   "language": "python",
   "name": "python3"
  },
  "language_info": {
   "codemirror_mode": {
    "name": "ipython",
    "version": 3
   },
   "file_extension": ".py",
   "mimetype": "text/x-python",
   "name": "python",
   "nbconvert_exporter": "python",
   "pygments_lexer": "ipython3",
   "version": "3.10.10"
  },
  "orig_nbformat": 4
 },
 "nbformat": 4,
 "nbformat_minor": 2
}
